2024-02-27 19:29:22,865 - urllib3.connectionpool - DEBUG - Starting new HTTPS connection (1): api.telegram.org:443
2024-02-27 19:29:23,015 - urllib3.connectionpool - DEBUG - https://api.telegram.org:443 "GET /bot7105353679:AAHGZZ3hLsQDJRgM-_aSPvozxqiC_WYLPek/getMe HTTP/1.1" 200 200
2024-02-27 19:29:23,016 - urllib3.connectionpool - DEBUG - Starting new HTTPS connection (1): api.telegram.org:443
2024-02-27 19:29:23,178 - urllib3.connectionpool - DEBUG - https://api.telegram.org:443 "GET /bot7105353679:AAHGZZ3hLsQDJRgM-_aSPvozxqiC_WYLPek/getUpdates?offset=1&timeout=20 HTTP/1.1" 200 480
2024-02-27 19:29:23,180 - urllib3.connectionpool - DEBUG - Starting new HTTPS connection (1): api.telegram.org:443
2024-02-27 19:29:23,664 - urllib3.connectionpool - DEBUG - https://api.telegram.org:443 "POST /bot7105353679:AAHGZZ3hLsQDJRgM-_aSPvozxqiC_WYLPek/sendMessage?chat_id=1020858404&text=%D0%9F%D1%80%D0%B8%D0%B2%D0%B5%D1%82%2C+%D0%B4%D0%BE%D1%80%D0%BE%D0%B3%D0%BE%D0%B9+%D0%BF%D0%BE%D0%BB%D1%8C%D0%B7%D0%BE%D0%B2%D0%B0%D1%82%D0%B5%D0%BB%D1%8C%2C+%D1%8F+%D0%BF%D0%BE%D0%BC%D0%BE%D1%89%D0%BD%D0%B8%D0%BA+%D0%B2+%D1%81%D1%84%D0%B5%D1%80%D0%B5+%D0%BF%D1%80%D0%BE%D0%B3%D1%80%D0%B0%D0%BC%D0%BC%D0%B8%D1%80%D0%BE%D0%B2%D0%B0%D0%BD%D0%B8%D1%8F+%D0%BD%D0%B0+%D1%8F%D0%B7%D1%8B%D0%BA%D0%B5+python&reply_markup=%7B%22keyboard%22%3A+%5B%5B%7B%22text%22%3A+%5B%22%2Fhelp%22%2C+%22%2Fsolve_task%22%2C+%22continue%22%5D%7D%5D%5D%2C+%22resize_keyboard%22%3A+true%7D HTTP/1.1" 400 125
2024-02-27 19:29:23,666 - TeleBot - ERROR - Threaded polling exception: A request to the Telegram API was unsuccessful. Error code: 400. Description: Bad Request: can't parse keyboard button: Field "text" must be of type String
2024-02-27 19:29:23,667 - TeleBot - ERROR - Exception traceback:
Traceback (most recent call last):
  File "G:\CoolProject\venv\Lib\site-packages\telebot\__init__.py", line 1074, in __threaded_polling
    self.worker_pool.raise_exceptions()
  File "G:\CoolProject\venv\Lib\site-packages\telebot\util.py", line 147, in raise_exceptions
    raise self.exception_info
  File "G:\CoolProject\venv\Lib\site-packages\telebot\util.py", line 90, in run
    task(*args, **kwargs)
  File "G:\CoolProject\venv\Lib\site-packages\telebot\__init__.py", line 6801, in _run_middlewares_and_handler
    result = handler['function'](message)
             ^^^^^^^^^^^^^^^^^^^^^^^^^^^^
  File "G:\CoolProject\бот_помощник\bot.py", line 56, in handle_start
    bot.send_message(
  File "G:\CoolProject\venv\Lib\site-packages\telebot\__init__.py", line 1549, in send_message
    apihelper.send_message(
  File "G:\CoolProject\venv\Lib\site-packages\telebot\apihelper.py", line 264, in send_message
    return _make_request(token, method_url, params=payload, method='post')
           ^^^^^^^^^^^^^^^^^^^^^^^^^^^^^^^^^^^^^^^^^^^^^^^^^^^^^^^^^^^^^^^
  File "G:\CoolProject\venv\Lib\site-packages\telebot\apihelper.py", line 162, in _make_request
    json_result = _check_result(method_name, result)
                  ^^^^^^^^^^^^^^^^^^^^^^^^^^^^^^^^^^
  File "G:\CoolProject\venv\Lib\site-packages\telebot\apihelper.py", line 189, in _check_result
    raise ApiTelegramException(method_name, result, result_json)
telebot.apihelper.ApiTelegramException: A request to the Telegram API was unsuccessful. Error code: 400. Description: Bad Request: can't parse keyboard button: Field "text" must be of type String

2024-02-27 19:29:34,542 - urllib3.connectionpool - DEBUG - https://api.telegram.org:443 "GET /bot7105353679:AAHGZZ3hLsQDJRgM-_aSPvozxqiC_WYLPek/getUpdates?offset=359361664&timeout=20 HTTP/1.1" 200 486
2024-02-27 19:29:34,543 - root - INFO - A new user has been added to the json file
2024-02-27 19:29:34,787 - urllib3.connectionpool - DEBUG - https://api.telegram.org:443 "POST /bot7105353679:AAHGZZ3hLsQDJRgM-_aSPvozxqiC_WYLPek/sendMessage?chat_id=1020858404&text=%D0%97%D0%B0%D0%B4%D0%B0%D0%B9+%D0%B2%D0%BE%D0%BF%D1%80%D0%BE%D1%81+%D0%B8+%D0%B7%D0%B0%D0%B4%D0%B0%D1%87%D1%83+%D0%B2+%D1%81%D0%BB%D0%B5%D0%B4%D1%83%D1%8E%D1%89%D0%B5%D0%BC+%D1%81%D0%BE%D0%BE%D0%B1%D1%89%D0%B5%D0%BD%D0%B8%D0%B5 HTTP/1.1" 200 537
2024-02-27 19:29:41,857 - urllib3.connectionpool - DEBUG - https://api.telegram.org:443 "GET /bot7105353679:AAHGZZ3hLsQDJRgM-_aSPvozxqiC_WYLPek/getUpdates?offset=359361665&timeout=20 HTTP/1.1" 200 479
2024-02-27 19:29:41,860 - urllib3.connectionpool - DEBUG - Starting new HTTPS connection (1): huggingface.co:443
2024-02-27 19:29:42,081 - urllib3.connectionpool - DEBUG - https://huggingface.co:443 "HEAD /mistralai/Mistral-7B-Instruct-v0.1/resolve/main/tokenizer_config.json HTTP/1.1" 200 0
2024-02-27 19:29:42,176 - urllib3.connectionpool - DEBUG - Starting new HTTP connection (1): localhost:1234
2024-02-27 19:29:42,950 - urllib3.connectionpool - DEBUG - https://api.telegram.org:443 "GET /bot7105353679:AAHGZZ3hLsQDJRgM-_aSPvozxqiC_WYLPek/getUpdates?offset=359361666&timeout=20 HTTP/1.1" 200 479
2024-02-27 19:29:42,952 - urllib3.connectionpool - DEBUG - Starting new HTTPS connection (1): api.telegram.org:443
2024-02-27 19:29:43,151 - urllib3.connectionpool - DEBUG - https://api.telegram.org:443 "POST /bot7105353679:AAHGZZ3hLsQDJRgM-_aSPvozxqiC_WYLPek/sendMessage?chat_id=1020858404&text=%2Fsolve_task+-+%D1%87%D1%82%D0%BE%D0%B1%D1%8B+%D0%B7%D0%B0%D0%B4%D0%B0%D1%82%D1%8C+%D0%B2%D0%BE%D0%BF%D1%80%D0%BE%D1%81+%D0%BD%D0%B5%D0%B9%D1%80%D0%BE%D1%81%D0%B5%D1%82%D0%B8%0A%2Fcontinue+-+%D0%BF%D1%80%D0%BE%D0%B4%D0%BE%D0%BB%D0%B6%D0%B8%D1%82%D1%8C+%D0%BE%D0%B1%D1%8A%D1%8F%D1%81%D0%BD%D0%B5%D0%BD%D0%B8%D0%B5+ HTTP/1.1" 200 722
2024-02-27 19:29:46,382 - TeleBot - ERROR - Infinity polling exception: HTTPConnectionPool(host='localhost', port=1234): Max retries exceeded with url: /v1/chat/completions (Caused by NewConnectionError('<urllib3.connection.HTTPConnection object at 0x00000167F10913D0>: Failed to establish a new connection: [WinError 10061] Подключение не установлено, т.к. конечный компьютер отверг запрос на подключение'))
2024-02-27 19:29:46,384 - TeleBot - ERROR - Exception traceback:
Traceback (most recent call last):
  File "G:\CoolProject\venv\Lib\site-packages\urllib3\connection.py", line 174, in _new_conn
    conn = connection.create_connection(
           ^^^^^^^^^^^^^^^^^^^^^^^^^^^^^
  File "G:\CoolProject\venv\Lib\site-packages\urllib3\util\connection.py", line 95, in create_connection
    raise err
  File "G:\CoolProject\venv\Lib\site-packages\urllib3\util\connection.py", line 85, in create_connection
    sock.connect(sa)
ConnectionRefusedError: [WinError 10061] Подключение не установлено, т.к. конечный компьютер отверг запрос на подключение

During handling of the above exception, another exception occurred:

Traceback (most recent call last):
  File "G:\CoolProject\venv\Lib\site-packages\urllib3\connectionpool.py", line 715, in urlopen
    httplib_response = self._make_request(
                       ^^^^^^^^^^^^^^^^^^^
  File "G:\CoolProject\venv\Lib\site-packages\urllib3\connectionpool.py", line 416, in _make_request
    conn.request(method, url, **httplib_request_kw)
  File "G:\CoolProject\venv\Lib\site-packages\urllib3\connection.py", line 244, in request
    super(HTTPConnection, self).request(method, url, body=body, headers=headers)
  File "G:\Python\Lib\http\client.py", line 1283, in request
    self._send_request(method, url, body, headers, encode_chunked)
  File "G:\Python\Lib\http\client.py", line 1329, in _send_request
    self.endheaders(body, encode_chunked=encode_chunked)
  File "G:\Python\Lib\http\client.py", line 1278, in endheaders
    self._send_output(message_body, encode_chunked=encode_chunked)
  File "G:\Python\Lib\http\client.py", line 1038, in _send_output
    self.send(msg)
  File "G:\Python\Lib\http\client.py", line 976, in send
    self.connect()
  File "G:\CoolProject\venv\Lib\site-packages\urllib3\connection.py", line 205, in connect
    conn = self._new_conn()
           ^^^^^^^^^^^^^^^^
  File "G:\CoolProject\venv\Lib\site-packages\urllib3\connection.py", line 186, in _new_conn
    raise NewConnectionError(
urllib3.exceptions.NewConnectionError: <urllib3.connection.HTTPConnection object at 0x00000167F10913D0>: Failed to establish a new connection: [WinError 10061] Подключение не установлено, т.к. конечный компьютер отверг запрос на подключение

During handling of the above exception, another exception occurred:

Traceback (most recent call last):
  File "G:\CoolProject\venv\Lib\site-packages\requests\adapters.py", line 486, in send
    resp = conn.urlopen(
           ^^^^^^^^^^^^^
  File "G:\CoolProject\venv\Lib\site-packages\urllib3\connectionpool.py", line 799, in urlopen
    retries = retries.increment(
              ^^^^^^^^^^^^^^^^^^
  File "G:\CoolProject\venv\Lib\site-packages\urllib3\util\retry.py", line 592, in increment
    raise MaxRetryError(_pool, url, error or ResponseError(cause))
urllib3.exceptions.MaxRetryError: HTTPConnectionPool(host='localhost', port=1234): Max retries exceeded with url: /v1/chat/completions (Caused by NewConnectionError('<urllib3.connection.HTTPConnection object at 0x00000167F10913D0>: Failed to establish a new connection: [WinError 10061] Подключение не установлено, т.к. конечный компьютер отверг запрос на подключение'))

During handling of the above exception, another exception occurred:

Traceback (most recent call last):
  File "G:\CoolProject\venv\Lib\site-packages\telebot\__init__.py", line 955, in infinity_polling
    self.polling(non_stop=True, timeout=timeout, long_polling_timeout=long_polling_timeout,
  File "G:\CoolProject\venv\Lib\site-packages\telebot\__init__.py", line 1043, in polling
    self.__threaded_polling(non_stop=non_stop, interval=interval, timeout=timeout, long_polling_timeout=long_polling_timeout,
  File "G:\CoolProject\venv\Lib\site-packages\telebot\__init__.py", line 1118, in __threaded_polling
    raise e
  File "G:\CoolProject\venv\Lib\site-packages\telebot\__init__.py", line 1074, in __threaded_polling
    self.worker_pool.raise_exceptions()
  File "G:\CoolProject\venv\Lib\site-packages\telebot\util.py", line 147, in raise_exceptions
    raise self.exception_info
  File "G:\CoolProject\venv\Lib\site-packages\telebot\util.py", line 90, in run
    task(*args, **kwargs)
  File "G:\CoolProject\бот_помощник\bot.py", line 90, in get_prompt
    reply_prompt(prompt, chat_id, msg)
  File "G:\CoolProject\бот_помощник\bot.py", line 43, in reply_prompt
    resp = send_request(json)
           ^^^^^^^^^^^^^^^^^^
  File "G:\CoolProject\бот_помощник\gpt.py", line 83, in send_request
    request = requests.post(url=gpt['URL'], headers=gpt['HEADERS'], json=json)
              ^^^^^^^^^^^^^^^^^^^^^^^^^^^^^^^^^^^^^^^^^^^^^^^^^^^^^^^^^^^^^^^^
  File "G:\CoolProject\venv\Lib\site-packages\requests\api.py", line 115, in post
    return request("post", url, data=data, json=json, **kwargs)
           ^^^^^^^^^^^^^^^^^^^^^^^^^^^^^^^^^^^^^^^^^^^^^^^^^^^^
  File "G:\CoolProject\venv\Lib\site-packages\requests\api.py", line 59, in request
    return session.request(method=method, url=url, **kwargs)
           ^^^^^^^^^^^^^^^^^^^^^^^^^^^^^^^^^^^^^^^^^^^^^^^^^
  File "G:\CoolProject\venv\Lib\site-packages\requests\sessions.py", line 589, in request
    resp = self.send(prep, **send_kwargs)
           ^^^^^^^^^^^^^^^^^^^^^^^^^^^^^^
  File "G:\CoolProject\venv\Lib\site-packages\requests\sessions.py", line 703, in send
    r = adapter.send(request, **kwargs)
        ^^^^^^^^^^^^^^^^^^^^^^^^^^^^^^^
  File "G:\CoolProject\venv\Lib\site-packages\requests\adapters.py", line 519, in send
    raise ConnectionError(e, request=request)
requests.exceptions.ConnectionError: HTTPConnectionPool(host='localhost', port=1234): Max retries exceeded with url: /v1/chat/completions (Caused by NewConnectionError('<urllib3.connection.HTTPConnection object at 0x00000167F10913D0>: Failed to establish a new connection: [WinError 10061] Подключение не установлено, т.к. конечный компьютер отверг запрос на подключение'))

